Workbook
Name a: 'GIS TPM+Eng Overview'!$G$14
Name aa: 'GIS TPM+Eng Overview'!$G$46
Name b: 'GIS TPM+Eng Overview'!$G$15
Name bb: 'GIS TPM+Eng Overview'!$G$47
Name d: 'GIS TPM+Eng Overview'!$G$16
Name dd: 'GIS TPM+Eng Overview'!$G$48
Name Doc_Controller: '275kV GIS TPM+Eng'!$G$117
Name Doc_Controller: '66kV GIS TPM+Eng'!$G$117
Name e: 'GIS TPM+Eng Overview'!$G$17
Name ee: 'GIS TPM+Eng Overview'!$G$49
Name ENG_Hours: '275kV GIS TPM+Eng'!$D$117
Name ENG_Hours: '66kV GIS TPM+Eng'!$D$117
Name ENG_Hours: '66kV GIS TPM+Eng'!$D$117
Name Engineer: '275kV GIS TPM+Eng'!$F$117
Name Engineer: '66kV GIS TPM+Eng'!$F$117
Name f: 'GIS TPM+Eng Overview'!$G$18
Name ff: 'GIS TPM+Eng Overview'!$G$50
Name g: 'GIS TPM+Eng Overview'!$G$19
Name gg: 'GIS TPM+Eng Overview'!$G$51
Name h: 'GIS TPM+Eng Overview'!$G$20
Name hh: 'GIS TPM+Eng Overview'!$G$52
Name i: 'GIS TPM+Eng Overview'!$G$21
Name ii: 'GIS TPM+Eng Overview'!$G$53
Name j: 'GIS TPM+Eng Overview'!$G$22
Name jj: 'GIS TPM+Eng Overview'!$G$54
Name k: 'GIS TPM+Eng Overview'!$G$23
Name kk: 'GIS TPM+Eng Overview'!$G$55
Name o: 'GIS TPM+Eng Overview'!$G$13
Name oo: 'GIS TPM+Eng Overview'!$G$45
Name q: 'GIS TPM+Eng Overview'!$G$12
Name qq: 'GIS TPM+Eng Overview'!$G$44
Name TPM: '275kV GIS TPM+Eng'!$E$117
Name TPM: '66kV GIS TPM+Eng'!$E$117
Name u: 'GIS TPM+Eng Overview'!$G$9
Name uu: 'GIS TPM+Eng Overview'!$G$41
Name v: 'GIS TPM+Eng Overview'!$G$10
Name vv: 'GIS TPM+Eng Overview'!$G$42
Name w: 'GIS TPM+Eng Overview'!$G$11
Name ww: 'GIS TPM+Eng Overview'!$G$43
Name x: 'GIS TPM+Eng Overview'!$G$6
Name xx: 'GIS TPM+Eng Overview'!$G$38
Name y: 'GIS TPM+Eng Overview'!$G$8
Name yy: 'GIS TPM+Eng Overview'!$G$40
Name z: 'GIS TPM+Eng Overview'!$G$7
Name zz: 'GIS TPM+Eng Overview'!$G$39

Sheet PM & Common
A1: <Project_Name>
A2: Project Management and Common Systems | B2: Month: | C2: 1 | D2: 2 | E2: 3 | F2: 4 | G2: 5 | H2: 6 | I2: 7 | J2: 8 | K2: 9 | L2: 10 | M2: 11 | N2: 12 | O2: 13 | P2: 14 | Q2: 15 | R2: 16 | S2: 17 | T2: 18 | U2: 19 | V2: 20 | W2: 21 | X2: 22 | Y2: 23 | Z2: 24 | AA2: 25 | AB2: 26 | AC2: 27 | AD2: 28 | AE2: 29 | AF2: 30 | AG2: 31 | AH2: 32 | AI2: 33 | AJ2: 34 | AK2: 35 | AL2: 36 | AM2: 37 | AR2: Proj. dur. (Mons): | AS2: 37
C3: 44743 | D3: 44774 | E3: 44805 | F3: 44835 | G3: 44866 | H3: 44896 | I3: 44927 | J3: 44958 | K3: 44986 | L3: 45017 | M3: 45047 | N3: 45078 | O3: 45108 | P3: 45139 | Q3: 45170 | R3: 45200 | S3: 45231 | T3: 45261 | U3: 45292 | V3: 45323 | W3: 45352 | X3: 45383 | Y3: 45413 | Z3: 45444 | AA3: 45474 | AB3: 45505 | AC3: 45536 | AD3: 45566 | AE3: 45597 | AF3: 45627 | AG3: 45658 | AH3: 45689 | AI3: 45717 | AJ3: 45748 | AK3: May-25 | AL3: 45809 | AM3: 45839 | AN3: Comments | AO3: Sub total hours | AP3: Hours Total: | AQ3: Hour Price (EUR): | AR3: Total cost (EUR): | AS3: Loading Avg.
A4: Project Timeline | C4: Basic Design | H4: Detailed design | L4: Manufacturing | S4: FAT | T4: Deliv. | V4: Installation | Y4: HAT | AB4: Sailaway | AF4: Offshore SAT | AJ4: Hold | AK4: As Built + Proj. Closure
A5: Basic Design | C5: Basic Design
A6: Detailed Design (Primary Parts) | H6: Detailed design
A7: Manufacturing (Primary Parts) | L7: Manufacturing
A8: FAT Testing (Primary Parts) | S8: FAT
A9: Detailed Design (Secondary Systems) | H9: Detailed design
A10: Manufacturing (Secondary Parts) | O10: Manufacturing
A11: FAT Testing (Secondary Parts) | R11: FAT
A12: Delivery to Site | T12: Deliv.
A13: Installation at Yard | V13: Installation
A14: HAT | Y14: HAT
A15: OSAT | AF15: Offshore SAT
A16: Project Closure | AK16: As Built + Proj. Closure
A18: General PM | C18: =C19+C32+C35+C36+C39+C45+C46+C47 -> 0 | D18: =D19+D32+D35+D36+D39+D45+D46+D47 -> 0 | E18: =E19+E32+E35+E36+E39+E45+E46+E47 -> 0 | F18: =F19+F32+F35+F36+F39+F45+F46+F47 -> 0 | G18: =G19+G32+G35+G36+G39+G45+G46+G47 -> 0 | H18: =H19+H32+H35+H36+H39+H45+H46+H47 -> 0 | I18: =I19+I32+I35+I36+I39+I45+I46+I47 -> 0 | J18: =J19+J32+J35+J36+J39+J45+J46+J47 -> 0 | ... AM18: =AM19+AM32+AM35+AM36+AM39+AM45+AM46+AM47 -> 0 | AP18: =SUM(C18:AM18) -> 0 | AQ18: =850/7.45 -> 114.09396 | AR18: =AP18*AQ18 -> 0 | AS18: =(AP18/135)/$AS$2 -> 0
A19: Project startup | C19: =SUM(C20:C31) -> 0 | D19: =SUM(D20:D31) -> 0 | E19: =SUM(E20:E31) -> 0 | F19: =SUM(F20:F31) -> 0 | G19: =SUM(G20:G31) -> 0 | H19: =SUM(H20:H31) -> 0 | I19: =SUM(I20:I31) -> 0 | J19: =SUM(J20:J31) -> 0 | ... AM19: =SUM(AM20:AM31) -> 0 | AO19: =SUM(C19:AM19) -> 0
A20: Contract Reading
A21: Project Plan
A22: Time Schedule
A23: WBS plan
A24: Risk&Opportunity Analysis
A25: Document Structure (Sharepoint + Tekdok)
A26: Requirement Register
A27: Stakeholder Analysis
A28: Procurement Plan
A29: Project Kick off Meeting Prep
A30: Project Kick off Meeting with Team
A31: Project Quality Plan
A32: Project group meetings | C32: =SUM(C33:C34) -> 0 | D32: =SUM(D33:D34) -> 0 | E32: =SUM(E33:E34) -> 0 | F32: =SUM(F33:F34) -> 0 | G32: =SUM(G33:G34) -> 0 | H32: =SUM(H33:H34) -> 0 | I32: =SUM(I33:I34) -> 0 | J32: =SUM(J33:J34) -> 0 | ... AM32: =SUM(AM33:AM34) -> 0 | AO32: =SUM(C32:AM32) -> 0
A33: Prep for meetings
A34: Meetings
A35: Project reviews (Milestones) | AO35: =SUM(C35:AM35) -> 0
A36: Project follow-up | C36: =SUM(C37:C38) -> 0 | D36: =SUM(D37:D38) -> 0 | E36: =SUM(E37:E38) -> 0 | F36: =SUM(F37:F38) -> 0 | G36: =SUM(G37:G38) -> 0 | H36: =SUM(H37:H38) -> 0 | I36: =SUM(I37:I38) -> 0 | J36: =SUM(J37:J38) -> 0 | ... AM36: =SUM(AM37:AM38) -> 0 | AO36: =SUM(C36:AM36) -> 0
A37: Economy Followup
A38: Followup on PM processes
A39: Project closing and evaluation | C39: =SUM(C40:C44) -> 0 | D39: =SUM(D40:D44) -> 0 | E39: =SUM(E40:E44) -> 0 | F39: =SUM(F40:F44) -> 0 | G39: =SUM(G40:G44) -> 0 | H39: =SUM(H40:H44) -> 0 | I39: =SUM(I40:I44) -> 0 | J39: =SUM(J40:J44) -> 0 | ... AM39: =SUM(AM40:AM44) -> 0 | AO39: =SUM(C39:AM39) -> 0
A40: Project closure Report
A41: Handover meeting to Service
...

Sheet Workload Histogram
A1: Project Duration: | B1: 1 | C1: 2 | D1: 3 | E1: 4 | F1: 5 | G1: 6 | H1: 7 | I1: 8 | J1: 9 | K1: 10 | L1: 11 | M1: 12 | N1: 13 | O1: 14 | P1: 15 | Q1: 16 | R1: 17 | S1: 18 | T1: 19 | U1: 20 | V1: 21 | W1: 22 | X1: 23 | Y1: 24 | Z1: 25 | AA1: 26 | AB1: 27 | AC1: 28 | AD1: 29 | AE1: 30 | AF1: 31 | AG1: 32 | AH1: 33 | AI1: 34 | AJ1: 35 | AK1: 36 | AL1: 37
A2: Month: | B2: 44743 | C2: 44774 | D2: 44805 | E2: 44835 | F2: 44866 | G2: 44896 | H2: 44927 | I2: 44958 | J2: 44986 | K2: 45017 | L2: 45047 | M2: 45078 | N2: 45108 | O2: 45139 | P2: 45170 | Q2: 45200 | R2: 45231 | S2: 45261 | T2: 45292 | U2: 45323 | V2: 45352 | W2: 45383 | X2: 45413 | Y2: 45444 | Z2: 45474 | AA2: 45505 | AB2: 45536 | AC2: 45566 | AD2: 45597 | AE2: 45627 | AF2: 45658 | AG2: 45689 | AH2: 45717 | AI2: 45748 | AJ2: May-25 | AK2: 45809 | AL2: 45839
B3: Basic Design | G3: Detailed design | K3: Manufacturing | R3: FAT | S3: Deliv. | U3: Installation | X3: HAT | AA3: Sailaway | AE3: Offshore SAT | AI3: Hold | AJ3: As Built + Proj. Closure
A4: Project Role: | AN4: Project Average:
A5: General PM | B5: ='PM & Common'!C18/160 -> 0 | C5: ='PM & Common'!D18/160 -> 0 | D5: ='PM & Common'!E18/160 -> 0 | E5: ='PM & Common'!F18/160 -> 0 | F5: ='PM & Common'!G18/160 -> 0 | G5: ='PM & Common'!H18/160 -> 0 | H5: ='PM & Common'!I18/160 -> 0 | I5: ='PM & Common'!J18/160 -> 0 | ... AL5: ='PM & Common'!AM18/160 -> 0 | AN5: =SUM(B5:AL5)/37 -> 0
A6: TPM, Mechanical (GIS, TR, SHR, EAT) | B6: ='PM & Common'!C49/160 -> 0 | C6: ='PM & Common'!D49/160 -> 0 | D6: ='PM & Common'!E49/160 -> 0 | E6: ='PM & Common'!F49/160 -> 0 | F6: ='PM & Common'!G49/160 -> 0 | G6: ='PM & Common'!H49/160 -> 0 | H6: ='PM & Common'!I49/160 -> 0 | I6: ='PM & Common'!J49/160 -> 0 | ... AL6: ='PM & Common'!AM49/160 -> 0 | AN6: =SUM(B6:AL6)/37 -> 0
A7: TPM, Electrical (Interfaces, Secondary Systems & Control Cable Eng.) | B7: ='PM & Common'!C92/160 -> 0 | C7: ='PM & Common'!D92/160 -> 0 | D7: ='PM & Common'!E92/160 -> 0 | E7: ='PM & Common'!F92/160 -> 0 | F7: ='PM & Common'!G92/160 -> 0 | G7: ='PM & Common'!H92/160 -> 0 | H7: ='PM & Common'!I92/160 -> 0 | I7: ='PM & Common'!J92/160 -> 0 | ... AL7: ='PM & Common'!AM92/160 -> 0 | AN7: =SUM(B7:AL7)/37 -> 0
A8: Lead Engineer, Control Cables | B8: ='PM & Common'!C118/160 -> 0 | C8: ='PM & Common'!D118/160 -> 0 | D8: ='PM & Common'!E118/160 -> 0 | E8: ='PM & Common'!F118/160 -> 0 | F8: ='PM & Common'!G118/160 -> 0 | G8: ='PM & Common'!H118/160 -> 0 | H8: ='PM & Common'!I118/160 -> 0 | I8: ='PM & Common'!J118/160 -> 0 | ... AL8: ='PM & Common'!AM118/160 -> 0 | AN8: =SUM(B8:AL8)/37 -> 0
A9: Lead Engineer, ICMS | B9: ='PM & Common'!C124/160 -> 0 | C9: ='PM & Common'!D124/160 -> 0 | D9: ='PM & Common'!E124/160 -> 0 | E9: ='PM & Common'!F124/160 -> 0 | F9: ='PM & Common'!G124/160 -> 0 | G9: ='PM & Common'!H124/160 -> 0 | H9: ='PM & Common'!I124/160 -> 0 | I9: ='PM & Common'!J124/160 -> 0 | ... AL9: ='PM & Common'!AM124/160 -> 0 | AN9: =SUM(B9:AL9)/37 -> 0
A10: Lead Engineer, CT/VT calculations | B10: ='PM & Common'!C135/160 -> 0 | C10: ='PM & Common'!D135/160 -> 0 | D10: ='PM & Common'!E135/160 -> 0 | E10: ='PM & Common'!F135/160 -> 0 | F10: ='PM & Common'!G135/160 -> 0 | G10: ='PM & Common'!H135/160 -> 0 | H10: ='PM & Common'!I135/160 -> 0 | I10: ='PM & Common'!J135/160 -> 0 | ... AL10: ='PM & Common'!AM135/160 -> 0 | AN10: =SUM(B10:AL10)/37 -> 0
A11: DK CPM (GIS + SCS&P + Overall) | B11: ='PM & Common'!C141/160 -> 0 | C11: ='PM & Common'!D141/160 -> 0 | D11: ='PM & Common'!E141/160 -> 0 | E11: ='PM & Common'!F141/160 -> 0 | F11: ='PM & Common'!G141/160 -> 0 | G11: ='PM & Common'!H141/160 -> 0 | H11: ='PM & Common'!I141/160 -> 0 | I11: ='PM & Common'!J141/160 -> 0 | ... AL11: ='PM & Common'!AM141/160 -> 0 | AN11: =SUM(B11:AL11)/37 -> 0
A12: DK QMiP | B12: ='PM & Common'!C151/160 -> 0 | C12: ='PM & Common'!D151/160 -> 0 | D12: ='PM & Common'!E151/160 -> 0 | E12: ='PM & Common'!F151/160 -> 0 | F12: ='PM & Common'!G151/160 -> 0 | G12: ='PM & Common'!H151/160 -> 0 | H12: ='PM & Common'!I151/160 -> 0 | I12: ='PM & Common'!J151/160 -> 0 | ... AL12: ='PM & Common'!AM151/160 -> 0 | AN12: =SUM(B12:AL12)/37 -> 0
A13: DK EHS | B13: ='PM & Common'!C161/160 -> 0 | C13: ='PM & Common'!D161/160 -> 0 | D13: ='PM & Common'!E161/160 -> 0 | E13: ='PM & Common'!F161/160 -> 0 | F13: ='PM & Common'!G161/160 -> 0 | G13: ='PM & Common'!H161/160 -> 0 | H13: ='PM & Common'!I161/160 -> 0 | I13: ='PM & Common'!J161/160 -> 0 | ... AL13: ='PM & Common'!AM161/160 -> 0 | AN13: =SUM(B13:AL13)/37 -> 0
A14: DK Purchaser / Strategic Procurement | B14: ='PM & Common'!C171/160 -> 0 | C14: ='PM & Common'!D171/160 -> 0 | D14: ='PM & Common'!E171/160 -> 0 | E14: ='PM & Common'!F171/160 -> 0 | F14: ='PM & Common'!G171/160 -> 0 | G14: ='PM & Common'!H171/160 -> 0 | H14: ='PM & Common'!I171/160 -> 0 | I14: ='PM & Common'!J171/160 -> 0 | ... AL14: ='PM & Common'!AM171/160 -> 0 | AN14: =SUM(B14:AL14)/37 -> 0
A15: Secondary Engineer Lead | B15: ='PM & Common'!C178/160 -> 0 | C15: ='PM & Common'!D178/160 -> 0 | D15: ='PM & Common'!E178/160 -> 0 | E15: ='PM & Common'!F178/160 -> 0 | F15: ='PM & Common'!G178/160 -> 0 | G15: ='PM & Common'!H178/160 -> 0 | H15: ='PM & Common'!I178/160 -> 0 | I15: ='PM & Common'!J178/160 -> 0 | ... AL15: ='PM & Common'!AM178/160 -> 0 | AN15: =SUM(B15:AL15)/37 -> 0
A16: Secondary Engineer (Engineering Assistance) | B16: ='PM & Common'!C188/160 -> 0 | C16: ='PM & Common'!D188/160 -> 0 | D16: ='PM & Common'!E188/160 -> 0 | E16: ='PM & Common'!F188/160 -> 0 | F16: ='PM & Common'!G188/160 -> 0 | G16: ='PM & Common'!H188/160 -> 0 | H16: ='PM & Common'!I188/160 -> 0 | I16: ='PM & Common'!J188/160 -> 0 | ... AL16: ='PM & Common'!AM188/160 -> 0 | AN16: =SUM(B16:AL16)/37 -> 0
A17: DK Document Controller | B17: ='PM & Common'!C198/160 -> 0 | C17: ='PM & Common'!D198/160 -> 0 | D17: ='PM & Common'!E198/160 -> 0 | E17: ='PM & Common'!F198/160 -> 0 | F17: ='PM & Common'!G198/160 -> 0 | G17: ='PM & Common'!H198/160 -> 0 | H17: ='PM & Common'!I198/160 -> 0 | I17: ='PM & Common'!J198/160 -> 0 | ... AL17: ='PM & Common'!AM198/160 -> 0 | AN17: =SUM(B17:AL17)/37 -> 0
A18: Contract Manager | B18: ='PM & Common'!C239/160 -> 0 | C18: ='PM & Common'!D239/160 -> 0 | D18: ='PM & Common'!E239/160 -> 0 | E18: ='PM & Common'!F239/160 -> 0 | F18: ='PM & Common'!G239/160 -> 0 | G18: ='PM & Common'!H239/160 -> 0 | H18: ='PM & Common'!I239/160 -> 0 | I18: ='PM & Common'!J239/160 -> 0 | ... AL18: ='PM & Common'!AM239/160 -> 0 | AN18: =SUM(B18:AL18)/37 -> 0
A20: EA1N Site Manager | B20: ='PM & Common'!C243/160 -> 0 | C20: ='PM & Common'!D243/160 -> 0 | D20: ='PM & Common'!E243/160 -> 0 | E20: ='PM & Common'!F243/160 -> 0 | F20: ='PM & Common'!G243/160 -> 0 | G20: ='PM & Common'!H243/160 -> 0 | H20: ='PM & Common'!I243/160 -> 0 | I20: ='PM & Common'!J243/160 -> 0 | ... AL20: ='PM & Common'!AM243/160 -> 0 | AN20: =SUM(B20:AL20)/37 -> 0
A21: EA1N Site HSE Manager | B21: ='PM & Common'!C244/160 -> 0 | C21: ='PM & Common'!D244/160 -> 0 | D21: ='PM & Common'!E244/160 -> 0 | E21: ='PM & Common'!F244/160 -> 0 | F21: ='PM & Common'!G244/160 -> 0 | G21: ='PM & Common'!H244/160 -> 0 | H21: ='PM & Common'!I244/160 -> 0 | I21: ='PM & Common'!J244/160 -> 0 | ... AL21: ='PM & Common'!AM244/160 -> 0 | AN21: =SUM(B21:AL21)/37 -> 0
A22: EA1N Site Commissioning Manager | B22: ='PM & Common'!C245/160 -> 0 | C22: ='PM & Common'!D245/160 -> 0 | D22: ='PM & Common'!E245/160 -> 0 | E22: ='PM & Common'!F245/160 -> 0 | F22: ='PM & Common'!G245/160 -> 0 | G22: ='PM & Common'!H245/160 -> 0 | H22: ='PM & Common'!I245/160 -> 0 | I22: ='PM & Common'!J245/160 -> 0 | ... AL22: ='PM & Common'!AM245/160 -> 0 | AN22: =SUM(B22:AL22)/37 -> 0

Sheet DK Project Travel Cost
A1: Activity: | B1: Travels Ext: | C1: Travels DK: | D1: Days:
A2: PM Travel
A3: Project Meetings
A4: TPM Mechanical Travel
A5: Transformer & SHR FAT
A6: EAT FAT
A7: GIS 66kV FAT
A8: GIS 275kV FAT
A9: TR & SHR Site
A10: GIS 66kV Site
A11: GIS 275kV Site
A12: TPM Electrical & Interface Travel
A13: Site Interfaces
... A24: 275kV GIS SAT
A26: Totals: | B26: =SUM(B2:B24) -> 0 | C26: =SUM(C2:C24) -> 0 | D26: =SUM(D2:D24) -> 0
A28: Cost pr. Travel Abroad: | B28: Price: | C28: Amount: | D28: total:
A29: Flight Tickets (round trip) | B29: 750 | C29: =B26 -> 0 | D29: =B29*C29 -> 0
A31: Cost pr. Travel DK: | B31: Price: | C31: Amount: | D31: total:
A32: Car travel 300km | B32: =((2*300*3.5)+(2*250))/7.45 -> 348.99329 | C32: =C26 -> 0 | D32: =B32*C32 -> 0
A34: Cost pr. Day:
A35: Hotel | B35: 130 | C35: =D26 -> 0 | D35: =B35*C35 -> 0
A36: Rental Car | B36: 0 | C36: =D26 -> 0 | D36: =B36*C36 -> 0
A37: Allowance/Meals | B37: 75 | C37: =D26 -> 0 | D37: =B37*C37 -> 0
A39: Total All: | D39: =SUM(D29:D37) -> 0

Sheet GIS TPM+Eng Overview
C3: 66kV GIS
C5: Project type | G5: Insert: | H5: Variable
C6: Project duration in months: | G6: 38 | H6: x
C7: Project duration of site activities in Weeks: | G7: 16 | H7: z
C8: Amount of switchgears: | G8: 4 | H8: y
C9: Manufacturing duration in months: | G9: 9 | H9: u
C10: If Onshore Project (Insert 1) | H10: v
C11: Total amount of typicals all switchgears | G11: 6 | H11: w
C12: Total amount of Bay's all switchgears | G12: 48 | H12: q
C13: Manpower for Installation | G13: 0 | H13: o
C14: LCC (Free Standing/Integrated) | G14: 48 | H14: a
C15: LCC Typicals | G15: 6 | H15: b
C16: Protection Panel (Free Standing) | G16: 48 | H16: d
C17: Protection Typicals | G17: 6 | H17: e
C18: Combined Panel (Free Standing/Integrated) | G18: 0 | H18: f
C19: Combined Panel Typicals | G19: 0 | H19: g
C20: SCADA Panel | G20: 0 | H20: h
C21: SCADA Panel Typicals | G21: 0 | H21: i
C22: US/UK Requirements | F22: x1,3 | G22: 1.3 | H22: j
C23: Pre-FAT Required | F23: x2 | G23: 2 | H23: k
C26: Engineering Hours | G26: 0
C27: Hours per month: | G27: =SUM(G29:G31)/x -> 178.84211
C28: Total All: | G28: =SUM(G29:G31) -> 6796
C29: Total TPM Hours: | G29: ='66kV GIS TPM+Eng'!E117 -> 1730.4
C30: Total Engineer Hours: | G30: ='66kV GIS TPM+Eng'!F117 -> 4369.6
C31: Total Doc. Controller Hours: | G31: ='66kV GIS TPM+Eng'!G117 -> 696
C35: 220kV GIS
C37: Project type | G37: Insert: | H37: Variable
C38: Project duration in months: | G38: 38 | H38: xx
C39: Project duration of site activities in Weeks: | G39: 6 | H39: zz
C40: Amount of switchgears: | G40: 4 | H40: yy
C41: Manufacturing duration in months: | G41: 9 | H41: uu
C42: If Onshore Project (Insert 1) | H42: vv
C43: Total amount of typicals all switchgears | G43: 1 | H43: ww
C44: Total amount of Bay's all switchgears | G44: 4 | H44: qq
C45: Manpower for Installation | G45: 0 | H45: oo
C46: LCC (Free Standing/Integrated) | G46: 4 | H46: aa
C47: LCC Typicals | G47: 2 | H47: bb
C48: Protection Panel (Free Standing) | G48: 4 | H48: dd
C49: Protection Typicals | G49: 2 | H49: ee
...

Sheet 66kV GIS TPM+Eng
A1: Engineering | C1: Hours: | D1: Total Hours: | E1: TPM | F1: Engineer | G1: Doc Controller | H1: Comments
A2: TT WBD Primary parts Before design freeze | B2: Give input to ITP | C2: 1 | D2: =C2*y -> 4 | E2: =D2 -> 4 | H2: Split between 66kV & 155kV
B3: Clarification of Single Line Diagram | C3: 1 | D3: =C3*y -> 4 | E3: =D3 -> 4
B4: Clarification of Layout and sections | C4: 1 | D4: =C4*y -> 4 | E4: =D4 -> 4
B5: Clarification of Constructional data | C5: 1 | D5: =C5*y -> 4 | E5: =D5 -> 4
B6: Clarification of 3D model | C6: 1 | D6: =C6*y -> 4 | E6: =D6 -> 4
B7: Clarification of SKID solution | C7: 0 | D7: =C7*y -> 0 | E7: =D7 -> 0 | H7: Not Relevant
B8: Clarification of accessibility to devices | C8: 2 | D8: =C8*y -> 8 | E8: =D8 -> 8 | H8: Part of SAG Scope, only coordination required
B9: Clarification of Earthing plan | C9: 2 | D9: =C9*y -> 8 | E9: =D9 -> 8 | H9: Only checks
B10: Clarification of device drawings for HV devices | C10: 2 | D10: =C10*y*j -> 10.4 | E10: =D10 -> 10.4
B11: Clarification of electrical load list for devices | C11: 2 | D11: =C11*y -> 8 | E11: =D11 -> 8
B12: Generation of Technical Description | C12: 0 | D12: =C12*y -> 0 | E12: =D12 -> 0 | H12: Not required, SAG provides
B13: Generation of design report acc to MTS | C13: 0 | D13: =C13*y -> 0 | E13: =D13 -> 0 | H13: Not required, SAG provides
B14: Design review meeting | C14: 3 | D14: =C14*y -> 12 | E14: =D14 -> 12 | H14: Design Review meeting with customer
B15: Document controlling | C15: 8 | D15: =C15*y -> 32 | G15: =D15 -> 32
A16: After design freeze | B16: Clarification of detailed steel drawings for manufact. | C16: 2 | D16: =C16*y -> 8 | E16: =D16 -> 8 | H16: Part of SAG Scope, only coordination required
B17: Clarification of detailed gangway drawings for manufact. | C17: 2 | D17: =C17*y -> 8 | E17: =D17 -> 8 | H17: Part of SAG Scope, only coordination required
B18: Clarification of detailed earthing for manufact. | C18: 0 | D18: =C18*y -> 0 | E18: =D18 -> 0 | H18: Part of SAG Scope
B19: Clarification of CB model, capacitive model, ferro ressonn | C19: 0 | D19: =C19*y -> 0 | E19: =D19 -> 0 | H19: Not required
B20: Clarification of FAT parameters - FAT plan | C20: 4 | D20: =C20*y -> 16 | E20: =D20 -> 16
B21: Clarification of SAT protocols | C21: 12 | D21: =C21*y -> 48 | E21: =D21 -> 48
B22: Clarification of outstanding points from FAT | C22: 2 | D22: =C22*y -> 8 | E22: =D22 -> 8
B23: Planning of logistics to merging point for primary parts | C23: 0 | D23: =C23*y -> 0 | E23: =D23 -> 0 | H23: Merging point not relevant
B24: Clarification of labeling | C24: 8 | D24: =C24*w*j -> 62.4 | E24: =D24 -> 62.4
B25: Follow up on delivery (NCR, missing parts etc.) | C25: 12 | D25: =C25*y -> 48 | E25: =D25 -> 48
B26: Clarification of As built for primary parts | C26: 8 | D26: =C26*y -> 32 | E26: =D26 -> 32
B27: Document controling | C27: 35 | D27: =C27*y -> 140 | G27: =D27 -> 140
A28: Activities for fabrication | B28: FAT Berlin | C28: 16 | D28: =C28*y -> 64 | E28: =D28 -> 64 | H28: 1 day travel + 1 day FAT
A29: Activities for transportation | B29: Planning of logistics from factory/merging point to site | C29: 8 | D29: =C29*y -> 32 | E29: =D29 -> 32
B30: Planning of logistic of direct supplies from factory to merging point | C30: 0 | D30: =C30*y -> 0 | E30: =D30 -> 0 | H30: Merging point not relevant
B31: Clarification of storage conditions at site | C31: 2 | D31: =C31*y -> 8 | E31: =D31 -> 8
A32: TT WBS Secondary parts Before design freeze | B32: Review of secondary device drawings | C32: 8 | D32: =C32*y -> 32 | F32: =D32 -> 32
B33: Creation of load list for devices | C33: 4 | D33: =C33*y -> 16 | F33: =D33 -> 16
A34: After design freeze | B34: Clarification of input from Employers requirements | C34: 2 | D34: =C34*y*j -> 10.4 | F34: =D34 -> 10.4
B35: Creation of interlocking concept | C35: 16 | D35: =C35*y*j -> 83.2 | F35: =D35 -> 83.2
B36: Creation of basic design document for Panels | C36: 8 | D36: =C36*y*j -> 41.6 | F36: =D36 -> 41.6
B37: Creation of wiring diagrams common drawings | C37: 16 | D37: =C37*y*j -> 83.2 | F37: =D37 -> 83.2
B38: Creation of Wiring diagrams LCC Typical x / Per typical | C38: 35 | D38: =(C38*b+C38*e+C38*g)*j -> 546 | F38: =D38 -> 546
B39: Creation of Wiring diagrams LCC Typical x / per swg ( meetering typpical) | C39: 17 | D39: =C39*y*j -> 88.4 | F39: =D39 -> 88.4
B40: Integration of Protection Devices in Panels | C40: 6 | D40: =C40*d+C40*f -> 288 | F40: =D40 -> 288
...

Sheet 275kV GIS TPM+Eng
A1: Engineering | C1: Hours: | D1: Total Hours: | E1: TPM | F1: Engineer | G1: Doc Controller | H1: Comments
A2: TT WBD Primary parts Before design freeze | B2: Give input to ITP | C2: 1 | D2: =C2*yy -> 4 | E2: =D2 -> 4 | H2: Split between 66kV & 155kV
B3: Clarification of Single Line Diagram | C3: 1 | D3: =C3*yy -> 4 | E3: =D3 -> 4
B4: Clarification of Layout and sections | C4: 1 | D4: =C4*yy -> 4 | E4: =D4 -> 4
B5: Clarification of Constructional data | C5: 1 | D5: =C5*yy -> 4 | E5: =D5 -> 4
B6: Clarification of 3D model | C6: 1 | D6: =C6*yy -> 4 | E6: =D6 -> 4
B7: Clarification of SKID solution | C7: 0 | D7: =C7*yy -> 0 | E7: =D7 -> 0 | H7: Not Relevant
B8: Clarification of accessibility to devices | C8: 2 | D8: =C8*yy -> 8 | E8: =D8 -> 8 | H8: Part of SAG Scope, only coordination required
B9: Clarification of Earthing plan | C9: 2 | D9: =C9*yy -> 8 | E9: =D9 -> 8 | H9: Only checks
B10: Clarification of device drawings for HV devices | C10: 2 | D10: =C10*yy*jj -> 10.4 | E10: =D10 -> 10.4
B11: Clarification of electrical load list for devices | C11: 2 | D11: =C11*yy -> 8 | E11: =D11 -> 8
B12: Generation of Technical Description | C12: 0 | D12: =C12*yy -> 0 | E12: =D12 -> 0 | H12: Not required, SAG provides
B13: Generation of design report acc to MTS | C13: 0 | D13: =C13*yy -> 0 | E13: =D13 -> 0 | H13: Not required, SAG provides
B14: Design review meeting | C14: 3 | D14: =C14*yy -> 12 | E14: =D14 -> 12 | H14: Design Review meeting with customer
B15: Document controlling | C15: 8 | D15: =C15*yy -> 32 | G15: =D15 -> 32
A16: After design freeze | B16: Clarification of detailed steel drawings for manufact. | C16: 2 | D16: =C16*yy -> 8 | E16: =D16 -> 8 | H16: Part of SAG Scope, only coordination required
B17: Clarification of detailed gangway drawings for manufact. | C17: 2 | D17: =C17*yy -> 8 | E17: =D17 -> 8 | H17: Part of SAG Scope, only coordination required
B18: Clarification of detailed earthing for manufact. | C18: 0 | D18: =C18*yy -> 0 | E18: =D18 -> 0 | H18: Part of SAG Scope, only coordination required
B19: Clarification of CB model, capacitive model, ferro ressonn | C19: 0 | D19: =C19*yy -> 0 | E19: =D19 -> 0 | H19: Not required
B20: Clarification of FAT parameters - FAT plan | C20: 4 | D20: =C20*yy -> 16 | E20: =D20 -> 16
B21: Clarification of SAT protocols | C21: 12 | D21: =C21*yy -> 48 | E21: =D21 -> 48
B22: Clarification of outstanding points from FAT | C22: 2 | D22: =C22*yy -> 8 | E22: =D22 -> 8
B23: Planning of logistics to merging point for primary parts | C23: 0 | D23: =C23*yy -> 0 | E23: =D23 -> 0 | H23: Merging point not relevant
B24: Clarification of labeling | C24: 8 | D24: =C24*ww*jj -> 10.4 | E24: =D24 -> 10.4
B25: Follow up on delivery (NCR, missing parts etc.) | C25: 12 | D25: =C25*yy -> 48 | E25: =D25 -> 48
B26: Clarification of As built for primary parts | C26: 8 | D26: =C26*yy -> 32 | E26: =D26 -> 32
B27: Document controling | C27: 35 | D27: =C27*yy -> 140 | G27: =D27 -> 140
A28: Activities for fabrication | B28: FAT Berlin | C28: 16 | D28: =C28*yy -> 64 | E28: =D28 -> 64 | H28: 1 day travel + 1 day FAT
A29: Activities for transportation | B29: Planning of logistics from factory/merging point to site | C29: 8 | D29: =C29*yy -> 32 | E29: =D29 -> 32
B30: Planning of logistic of direct supplies from factory to merging point | C30: 0 | D30: =C30*yy -> 0 | E30: =D30 -> 0 | H30: Merging point not relevant
B31: Clarification of storage conditions at site | C31: 2 | D31: =C31*yy -> 8 | E31: =D31 -> 8 | H31: Handled in 66kV
A32: TT WBS Secondary parts Before design freeze | B32: Review of secondary device drawings | C32: 8 | D32: =C32*yy -> 32 | F32: =D32 -> 32
B33: Creation of load list for devices | C33: 4 | D33: =C33*yy -> 16 | F33: =D33 -> 16
A34: After design freeze | B34: Clarification of input from Employers requirements | C34: 2 | D34: =C34*yy*jj -> 10.4 | F34: =D34 -> 10.4
B35: Creation of interlocking concept | C35: 16 | D35: =C35*yy*jj -> 83.2 | F35: =D35 -> 83.2
B36: Creation of basic design document LCC & BCU | C36: 8 | D36: =C36*yy*jj -> 41.6 | F36: =D36 -> 41.6
B37: Creation of wiring diagrams common drawings | C37: 16 | D37: =C37*yy*jj -> 83.2 | F37: =D37 -> 83.2
B38: Creation of Wiring diagrams LCC Typical x / Per typical | C38: 35 | D38: =(C38*bb+C38*ee+C38*gg)*jj -> 182 | F38: =D38 -> 182
B39: Creation of Wiring diagrams LCC Typical x / per swg ( meetering typpical) | C39: 17 | D39: =C39*yy*jj -> 88.4 | F39: =D39 -> 88.4
B40: Integration of Protection Devices in Panels | C40: 6 | D40: =C40*dd+C40*ff -> 24 | F40: =D40 -> 24
...
